
[ 2024-09-18 14:11:56.536241 ] TypeError: 'NoneType' object is not subscriptable

Traceback (most recent call last):
  File "/Users/aarushmahajan/PycharmProjects/mtms/mtms/src/mtms/__init__.py", line 11, in run
    from base.menu import main_menu
  File "/Users/aarushmahajan/PycharmProjects/mtms/mtms/src/mtms/base/menu/main_menu.py", line 6, in <module>
    'login'						:	fn.lang_dict['login']
                   ~~~~~~~~~~~~^^^^^^^^^

[ 2024-09-18 14:46:07.617421 ] TypeError: 'NoneType' object is not subscriptable

Traceback (most recent call last):
  File "/Users/aarushmahajan/PycharmProjects/mtms/mtms/src/mtms/__init__.py", line 11, in run
    from base.menu import main_menu
  File "/Users/aarushmahajan/PycharmProjects/mtms/mtms/src/mtms/base/menu/main_menu.py", line 6, in <module>
    'login'						:	fn.lang_dict['login']
                   ~~~~~~~~~~~~^^^^^^^^^

[ 2024-09-18 14:50:54.579639 ] Exception: ERROR: Failed to connect database!MySQL Error Code is '2003'

Traceback (most recent call last):
  File "/Users/aarushmahajan/PycharmProjects/mtms/.venv/lib/python3.11/site-packages/mysql/connector/network.py", line 509, in open_connection
    self.sock.connect(sockaddr)
TimeoutError: [Errno 60] Operation timed out

During handling of the above exception, another exception occurred:

Traceback (most recent call last):
  File "/Users/aarushmahajan/PycharmProjects/mtms/mtms/src/mtms/base/functions/functions.py", line 513, in firstThingsFirst
    db = configs.mysql.connector.connect(
         ^^^^^^^^^^^^^^^^^^^^^^^^^^^^^^^^
  File "/Users/aarushmahajan/PycharmProjects/mtms/.venv/lib/python3.11/site-packages/mysql/connector/__init__.py", line 179, in connect
    return MySQLConnection(*args, **kwargs)
           ^^^^^^^^^^^^^^^^^^^^^^^^^^^^^^^^
  File "/Users/aarushmahajan/PycharmProjects/mtms/.venv/lib/python3.11/site-packages/mysql/connector/connection.py", line 95, in __init__
    self.connect(**kwargs)
  File "/Users/aarushmahajan/PycharmProjects/mtms/.venv/lib/python3.11/site-packages/mysql/connector/abstracts.py", line 716, in connect
    self._open_connection()
  File "/Users/aarushmahajan/PycharmProjects/mtms/.venv/lib/python3.11/site-packages/mysql/connector/connection.py", line 206, in _open_connection
    self._socket.open_connection()
  File "/Users/aarushmahajan/PycharmProjects/mtms/.venv/lib/python3.11/site-packages/mysql/connector/network.py", line 511, in open_connection
    raise errors.InterfaceError(
mysql.connector.errors.InterfaceError: 2003: Can't connect to MySQL server on 'cs-cbse.database.windows.net:3306' (60 Operation timed out)

During handling of the above exception, another exception occurred:

Traceback (most recent call last):
  File "/Users/aarushmahajan/PycharmProjects/mtms/mtms/src/mtms/__init__.py", line 10, in run
    fn.firstThingsFirst()
  File "/Users/aarushmahajan/PycharmProjects/mtms/mtms/src/mtms/base/functions/functions.py", line 533, in firstThingsFirst
    raise Exception(lang_dict['error_failed_to_connect_database'] + 'MySQL Error Code is \'' + str(err.errno) + '\'')

[ 2024-09-18 15:02:18.142844 ] Exception: ERROR: Failed to connect database!MySQL Error Code is '2003'

Traceback (most recent call last):
  File "/Users/aarushmahajan/PycharmProjects/mtms/.venv/lib/python3.11/site-packages/mysql/connector/network.py", line 509, in open_connection
    self.sock.connect(sockaddr)
TimeoutError: [Errno 60] Operation timed out

During handling of the above exception, another exception occurred:

Traceback (most recent call last):
  File "/Users/aarushmahajan/PycharmProjects/mtms/mtms/src/mtms/base/functions/functions.py", line 513, in firstThingsFirst
    db = configs.mysql.connector.connect(
         ^^^^^^^^^^^^^^^^^^^^^^^^^^^^^^^^
  File "/Users/aarushmahajan/PycharmProjects/mtms/.venv/lib/python3.11/site-packages/mysql/connector/__init__.py", line 179, in connect
    return MySQLConnection(*args, **kwargs)
           ^^^^^^^^^^^^^^^^^^^^^^^^^^^^^^^^
  File "/Users/aarushmahajan/PycharmProjects/mtms/.venv/lib/python3.11/site-packages/mysql/connector/connection.py", line 95, in __init__
    self.connect(**kwargs)
  File "/Users/aarushmahajan/PycharmProjects/mtms/.venv/lib/python3.11/site-packages/mysql/connector/abstracts.py", line 716, in connect
    self._open_connection()
  File "/Users/aarushmahajan/PycharmProjects/mtms/.venv/lib/python3.11/site-packages/mysql/connector/connection.py", line 206, in _open_connection
    self._socket.open_connection()
  File "/Users/aarushmahajan/PycharmProjects/mtms/.venv/lib/python3.11/site-packages/mysql/connector/network.py", line 511, in open_connection
    raise errors.InterfaceError(
mysql.connector.errors.InterfaceError: 2003: Can't connect to MySQL server on 'cs-cbse.database.windows.net:3306' (60 Operation timed out)

During handling of the above exception, another exception occurred:

Traceback (most recent call last):
  File "/Users/aarushmahajan/PycharmProjects/mtms/mtms/src/mtms/__init__.py", line 10, in run
    fn.firstThingsFirst()
  File "/Users/aarushmahajan/PycharmProjects/mtms/mtms/src/mtms/base/functions/functions.py", line 533, in firstThingsFirst
    raise Exception(lang_dict['error_failed_to_connect_database'] + 'MySQL Error Code is \'' + str(err.errno) + '\'')
